<?xml version="1.0" encoding="utf-8"?>
<!-- This URDF was automatically created by SolidWorks to URDF Exporter! Originally created by Stephen Brawner (brawner@gmail.com)
     Commit Version: 1.5.0-0-g9aa0fdb  Build Version: 1.5.7004.21443
     For more information, please see http://wiki.ros.org/sw_urdf_exporter -->
<robot name="quadruped_model" xmlns:xacro="http://ros.org/wiki/xacro">

    <!-- <xacro:include filename="$(find velodyne_description)/urdf/VLP-16.urdf.xacro"/>
    <VLP-16 parent="base_link" name="velodyne" topic="/velodyne_points" >
        <origin xyz="0.26  0  0.118" rpy="0 0 0" />
    </VLP-16>    -->


    <link name="imu_link">
      <inertial>
        <mass value="0.1"/>
        <origin rpy="0 0 0" xyz="0 0 0"/>
        <inertia ixx="0.0001" ixy="0" ixz="0" iyy="0.000001" iyz="0" izz="0.0001"/>
      </inertial>
      <visual>
        <origin rpy="0 0 0" xyz="0 0 0"/>
        <geometry>
          <box size="0.06 0.06 0.02"/>
        </geometry>
      </visual>
      <collision>
        <origin rpy="0 0 0" xyz="0 0 0"/>
        <geometry>
          <box size="0.06 0.06 0.02"/>
        </geometry>
      </collision>
    </link>
    <joint name="imu_joint" type="fixed">
        <axis xyz="0 0 0"/>  <!--0 1 0 -->
        <origin xyz="0.13 0 0.12" rpy="0 0 0"/>
        <parent link="base"/>
        <child link="imu_link"/>
    </joint>

    <!-- <link name = "world"/>
    <joint name="body_link" type="fixed">
      <parent link="world"/>
      <child link="base_link"/>
      <origin xyz="0 0 0" rpy="0 0 0" />
      <axis xyz="0 0 1" />
    </joint> -->

  <!-- <xacro:arg name="laser_visual"  default="false"/> -->
  <!-- <xacro:arg name="camera_visual" default="false"/> -->
  <!-- <xacro:arg name="imu_visual"    default="false"/> -->
  <!-- <xacro:arg name="kinect_enabled"    default="true"/> -->
    <xacro:include filename="$(find simpledog)/urdf/simpledog_gazebo.urdf.xacro" />
    <xacro:include filename="$(find simpledog)/urdf/joint_gazebo.urdf.xacro" />
    <!-- <xacro:include filename="$(find simpledog)/urdf/kinect.urdf.xacro"/> -->
    <xacro:include filename="$(find simpledog)/urdf/foot_sensor_gazebo.urdf.xacro" />

    <!--load kinect urdf-->
    <!-- <xacro:if value="$(arg kinect_enabled)">
      <xacro:kinect_camera prefix="camera" robot_namespace="$(arg robot_namespace)"/>
      <joint name="kinect_frame_joint" type="fixed">
        <origin xyz="0.5 0 0.075" rpy="0 0.8 0" />
        <parent link="base_link"/>
        <child link="camera_link"/>
      </joint>
    </xacro:if> -->

  <link name="zed_base_link">
    <origin xyz="0 0 0" rpy="0 0 0"/>
  </link>
  <joint name="zed_base_joint" type="fixed">
    <origin xyz="0.48 0.0 0.15" rpy="0 0.8 0" />
    <parent link="base"/>
    <child link="zed_base_link"/>
  </joint>

  <!-- simple dog joints macros configure the joint driver and param-->
  <xacro:simpledog_joint joint_prefix="LF_HAA"> </xacro:simpledog_joint>
  <xacro:simpledog_joint joint_prefix="LF_HFE"> </xacro:simpledog_joint>
  <xacro:simpledog_joint joint_prefix="LF_KFE"> </xacro:simpledog_joint>
  <xacro:simpledog_joint joint_prefix="RF_HAA"> </xacro:simpledog_joint>
  <xacro:simpledog_joint joint_prefix="RF_HFE"> </xacro:simpledog_joint>
  <xacro:simpledog_joint joint_prefix="RF_KFE"> </xacro:simpledog_joint>
  <xacro:simpledog_joint joint_prefix="RH_HAA"> </xacro:simpledog_joint>
  <xacro:simpledog_joint joint_prefix="RH_HFE"> </xacro:simpledog_joint>
  <xacro:simpledog_joint joint_prefix="RH_KFE"> </xacro:simpledog_joint>
  <xacro:simpledog_joint joint_prefix="LH_HAA"> </xacro:simpledog_joint>
  <xacro:simpledog_joint joint_prefix="LH_HFE"> </xacro:simpledog_joint>
  <xacro:simpledog_joint joint_prefix="LH_KFE"> </xacro:simpledog_joint>

  <xacro:simpledog_foot_sensors foot_prefix="LF_FOOT" joint_prefix="LF_SHANK"> </xacro:simpledog_foot_sensors>
  <xacro:simpledog_foot_sensors foot_prefix="RF_FOOT" joint_prefix="RF_SHANK"> </xacro:simpledog_foot_sensors>
  <xacro:simpledog_foot_sensors foot_prefix="RH_FOOT" joint_prefix="RH_SHANK"> </xacro:simpledog_foot_sensors>
  <xacro:simpledog_foot_sensors foot_prefix="LH_FOOT" joint_prefix="LH_SHANK"> </xacro:simpledog_foot_sensors>

    <link name="base">
        <visual>
            <origin rpy="0 0 0" xyz="0 0 0"/>
            <geometry>
                <box size="0.000001 0.000001 0.000001"/>
            </geometry>
        </visual>
    </link>

    <joint name="floating_base" type="fixed">
        <origin rpy="0 0 0" xyz="0 0 0"/>
        <parent link="base"/>
        <child link="base_inertia"/>
    </joint>

  <link
    name="base_inertia">
    <inertial>
      <origin
        xyz="0.006699 -0.000736 0.001288"
        rpy="0 0 0" />
      <mass
        value="37.801" />
      <inertia
        ixx="0.263893"
        ixy="0"
        ixz="0"
        iyy="2.018032"
        iyz="0"
        izz="2.056458" />
    </inertial>
    <visual>
      <origin
        xyz="0 0 0"
        rpy="0 0 0" />
      <geometry>
        <mesh
          filename="package://simpledog/meshes/quadruped/base_link.STL" />
      </geometry>
      <material
        name="">
        <color
          rgba="0 0 1 1" />
      </material>
    </visual>
    <collision>
      <origin
        xyz="0 0 0"
        rpy="0 0 0" />
      <geometry>
        <mesh
          filename="package://simpledog/meshes/quadruped/base_link.STL" />
      </geometry>
    </collision>
  </link>
  <link
    name="LF_HIP">
    <inertial>
      <origin
        xyz="0.000688 0.10488 -0.003776"
        rpy="0 0 0" />
      <mass
        value="2.9231" />
      <inertia
        ixx="0.004820"
        ixy="0"
        ixz="0"
        iyy="0.007868"
        iyz="0"
        izz="0.008241" />
    </inertial>
    <visual>
      <origin
        xyz="0 0 0"
        rpy="0 0 0" />
      <geometry>
        <mesh
          filename="package://simpledog/meshes/quadruped/Origin_front_left_1_link.STL" />
      </geometry>
      <material
        name="">
        <color
          rgba="0.79216 0.81961 0.93333 1" />
      </material>
    </visual>
    <collision>
      <origin
        xyz="0 0 0"
        rpy="0 0 0" />
      <geometry>
        <mesh
          filename="package://simpledog/meshes/quadruped/Origin_front_left_1_link.STL" />
      </geometry>
    </collision>
  </link>
  <joint
    name="LF_HAA"
    type="revolute">
    <origin
      xyz="0.427 0.075 -0.0095"
      rpy="0 1.5708 0" />
    <parent
      link="base" />
    <child
      link="LF_HIP" />
    <axis
      xyz="0 0 1" />
      <limit
      effort="60"
      velocity="10"
      lower="-3.0"
      upper="3.0"/>

  </joint>
  <link
    name="LF_THIGH">
    <inertial>
      <origin
        xyz="0.18475 3.2E-05 0.12906"
        rpy="0 0 0" />
      <mass
        value="4.2164" />
      <inertia
        ixx="0.006286"
        ixy="0"
        ixz="0"
        iyy="0.028156"
        iyz="0"
        izz="0.029242" />
    </inertial>
    <visual>
      <origin
        xyz="0 0 0"
        rpy="0 0 0" />
      <geometry>
        <mesh
          filename="package://simpledog/meshes/quadruped/Origin_front_left_2_link.STL" />
      </geometry>
      <material
        name="">
        <color
          rgba="0.79216 0.81961 0.93333 1" />
      </material>
    </visual>
    <collision>
      <origin
        xyz="0 0 0"
        rpy="0 0 0" />
      <geometry>
        <mesh
          filename="package://simpledog/meshes/quadruped/Origin_front_left_2_link.STL" />
      </geometry>
    </collision>
  </link>
  <joint
    name="LF_HFE"
    type="continuous">
    <origin
      xyz="0 0 0"
      rpy="-1.5708 0 0" />
    <parent
      link="LF_HIP" />
    <child
      link="LF_THIGH" />
    <axis
      xyz="0 0 1" />
      <limit
      effort="60"
      velocity="10"
      lower="-7.0"
      upper="7.0"/>

  </joint>
  <link
    name="LF_SHANK">
    <inertial>
      <origin
        xyz="0.20231 0.000199 0.22543"
        rpy="0 0 0" />
      <mass
        value="0.44457" />
      <inertia
        ixx="0.000385"
        ixy="0"
        ixz="0"
        iyy="0.006223"
        iyz="0"
        izz="0.006502" />
    </inertial>
    <visual>
      <origin
        xyz="0 0 0"
        rpy="0 0 0" />
      <geometry>
        <mesh
          filename="package://simpledog/meshes/quadruped/Origin_front_left_3_link.STL" />
      </geometry>
      <material
        name="">
        <color
          rgba="0.79216 0.81961 0.93333 1" />
      </material>
    </visual>
    <collision>
      <origin
        xyz="0 0 0"
        rpy="0 0 0" />
      <geometry>
        <mesh
          filename="package://simpledog/meshes/quadruped/Origin_front_left_3_link.STL" />
      </geometry>
    </collision>
  </link>
  <joint
    name="LF_KFE"
    type="continuous">
    <origin
      xyz="0.308 0 0"
      rpy="0 0 0" />
    <parent
      link="LF_THIGH" />
    <child
      link="LF_SHANK" />
    <axis
      xyz="0 0 1" />
      <limit
      effort="60"
      velocity="10"
      lower="-3.0"
      upper="3.0"/>

  </joint>
  <link
    name="LF_FOOT">
    <inertial>
      <origin
        xyz="0.022126 -1.2357E-13 0.00049896"
        rpy="0 0 0" />
      <mass
        value="0.03332" />
      <inertia
        ixx="0.000014"
        ixy="0"
        ixz="0"
        iyy="0.000014"
        iyz="0"
        izz="0.000019" />
    </inertial>
    <visual>
      <origin
        xyz="0 0 0"
        rpy="0 0 0" />
      <geometry>
        <mesh
          filename="package://simpledog/meshes/quadruped/Origin_lf_foot_link.STL" />
      </geometry>
      <material
        name="">
        <color
          rgba="0 0 0 1" />
      </material>
    </visual>
    <collision>
      <origin
        xyz="0 0 0"
        rpy="0 0 0" />
      <geometry>
        <mesh
          filename="package://simpledog/meshes/quadruped/Origin_lf_foot_link.STL" />
      </geometry>
    </collision>
  </link>
  <joint
    name="LF_ADAPTER"
    type="fixed">
    <origin
      xyz="0.308 0 0.23"
      rpy="0 0 0" />
    <parent
      link="LF_SHANK" />
    <child
      link="LF_FOOT" />
    <axis
      xyz="0 0 0" />
  </joint>
  <link
    name="RF_HIP">
    <inertial>
      <origin
        xyz="-0.000688 0.104882 0.003776"
        rpy="0 0 0" />
      <mass
        value="2.923111" />
      <inertia
        ixx="0.004820"
        ixy="0"
        ixz="0"
        iyy="0.007868"
        iyz="0"
        izz="0.008241" />
    </inertial>
    <visual>
      <origin
        xyz="0 0 0"
        rpy="0 0 0" />
      <geometry>
        <mesh
          filename="package://simpledog/meshes/quadruped/Origin_front_right_1_link.STL" />
      </geometry>
      <material
        name="">
        <color
          rgba="0.79216 0.81961 0.93333 1" />
      </material>
    </visual>
    <collision>
      <origin
        xyz="0 0 0"
        rpy="0 0 0" />
      <geometry>
        <mesh
          filename="package://simpledog/meshes/quadruped/Origin_front_right_1_link.STL" />
      </geometry>
    </collision>
  </link>
  <joint
    name="RF_HAA"
    type="revolute">
    <origin
      xyz="0.427 -0.075 -0.0095"
      rpy="3.1416 1.5708 0" />
    <parent
      link="base" />
    <child
      link="RF_HIP" />
    <axis
      xyz="0 0 1" />
      <limit
      effort="60"
      velocity="10"
      lower="-3.0"
      upper="3.0"/>

  </joint>
  <link
    name="RF_THIGH">
    <inertial>
      <origin
        xyz="0.184747 3.2E-05 0.129056"
        rpy="0 0 0" />
      <mass
        value="4.216358" />
      <inertia
        ixx="0.006286"
        ixy="0"
        ixz="0"
        iyy="0.028156"
        iyz="0"
        izz="0.029242" />
    </inertial>
    <visual>
      <origin
        xyz="0 0 0"
        rpy="0 0 0" />
      <geometry>
        <mesh
          filename="package://simpledog/meshes/quadruped/Origin_front_right_2_link.STL" />
      </geometry>
      <material
        name="">
        <color
          rgba="0.79216 0.81961 0.93333 1" />
      </material>
    </visual>
    <collision>
      <origin
        xyz="0 0 0"
        rpy="0 0 0" />
      <geometry>
        <mesh
          filename="package://simpledog/meshes/quadruped/Origin_front_right_2_link.STL" />
      </geometry>
    </collision>
  </link>
  <joint
    name="RF_HFE"
    type="continuous">
    <origin
      xyz="0 0 0"
      rpy="-1.5708 0 0" />
    <parent
      link="RF_HIP" />
    <child
      link="RF_THIGH" />
    <axis
      xyz="0 0 1" />
      <limit
      effort="60"
      velocity="10"
      lower="-7.0"
      upper="7.0"/>

  </joint>
  <link
    name="RF_SHANK">
    <inertial>
      <origin
        xyz="0.202313 0.000199 0.225432"
        rpy="0 0 0" />
      <mass
        value="0.444569" />
      <inertia
        ixx="0.000385"
        ixy="0"
        ixz="0"
        iyy="0.006223"
        iyz="0"
        izz="0.006502" />
    </inertial>
    <visual>
      <origin
        xyz="0 0 0"
        rpy="0 0 0" />
      <geometry>
        <mesh
          filename="package://simpledog/meshes/quadruped/Origin_front_right_3_link.STL" />
      </geometry>
      <material
        name="">
        <color
          rgba="0.79216 0.81961 0.93333 1" />
      </material>
    </visual>
    <collision>
      <origin
        xyz="0 0 0"
        rpy="0 0 0" />
      <geometry>
        <mesh
          filename="package://simpledog/meshes/quadruped/Origin_front_right_3_link.STL" />
      </geometry>
    </collision>
  </link>
  <joint
    name="RF_KFE"
    type="continuous">
    <origin
      xyz="0.308 0 0"
      rpy="0 0 0" />
    <parent
      link="RF_THIGH" />
    <child
      link="RF_SHANK" />
    <axis
      xyz="0 0 1" />
      <limit
      effort="60"
      velocity="10"
      lower="-3.0"
      upper="3.0"/>

  </joint>
  <link
    name="RF_FOOT">
    <inertial>
      <origin
        xyz="0.022126 -4.4892E-13 -1.0375E-06"
        rpy="0 0 0" />
      <mass
        value="0.03332" />
      <inertia
        ixx="0.000014"
        ixy="0"
        ixz="0"
        iyy="0.000014"
        iyz="0"
        izz="0.000019" />
    </inertial>
    <visual>
      <origin
        xyz="0 0 0"
        rpy="0 0 0" />
      <geometry>
        <mesh
          filename="package://simpledog/meshes/quadruped/Orgin_rf_foot_link.STL" />
      </geometry>
      <material
        name="">
        <color
          rgba="0 0 0 1" />
      </material>
    </visual>
    <collision>
      <origin
        xyz="0 0 0"
        rpy="0 0 0" />
      <geometry>
        <mesh
          filename="package://simpledog/meshes/quadruped/Orgin_rf_foot_link.STL" />
      </geometry>
    </collision>
  </link>
  <joint
    name="RF_ADAPTER"
    type="fixed">
    <origin
      xyz="0.308 0 0.22053"
      rpy="0 0 0" />
    <parent
      link="RF_SHANK" />
    <child
      link="RF_FOOT" />
    <axis
      xyz="0 0 0" />
  </joint>
  <link
    name="RH_HIP">
    <inertial>
      <origin
        xyz="0.000688 0.104882 0.003776"
        rpy="0 0 0" />
      <mass
        value="2.923111" />
      <inertia
        ixx="0.004820"
        ixy="0"
        ixz="0"
        iyy="0.007868"
        iyz="0"
        izz="0.008241" />
    </inertial>
    <visual>
      <origin
        xyz="0 0 0"
        rpy="0 0 0" />
      <geometry>
        <mesh
          filename="package://simpledog/meshes/quadruped/Origin_rear_right_1_link.STL" />
      </geometry>
      <material
        name="">
        <color
          rgba="0.79216 0.81961 0.93333 1" />
      </material>
    </visual>
    <collision>
      <origin
        xyz="0 0 0"
        rpy="0 0 0" />
      <geometry>
        <mesh
          filename="package://simpledog/meshes/quadruped/Origin_rear_right_1_link.STL" />
      </geometry>
    </collision>
  </link>
  <joint
    name="RH_HAA"
    type="revolute">
    <origin
      xyz="-0.427 -0.075 -0.0095"
      rpy="3.1416 1.5708 0" />
    <parent
      link="base" />
    <child
      link="RH_HIP" />
    <axis
      xyz="0 0 1" />
      <limit
      effort="60"
      velocity="10"
      lower="-3.0"
      upper="3.0"/>

  </joint>
  <link
    name="RH_THIGH">
    <inertial>
      <origin
        xyz="0.184747 3.2E-05 0.129056"
        rpy="0 0 0" />
      <mass
        value="4.216358" />
      <inertia
        ixx="0.006286"
        ixy="0"
        ixz="0"
        iyy="0.028156"
        iyz="0"
        izz="0.029242" />
    </inertial>
    <visual>
      <origin
        xyz="0 0 0"
        rpy="0 0 0" />
      <geometry>
        <mesh
          filename="package://simpledog/meshes/quadruped/Origin_rear_right_2_link.STL" />
      </geometry>
      <material
        name="">
        <color
          rgba="0.79216 0.81961 0.93333 1" />
      </material>
    </visual>
    <collision>
      <origin
        xyz="0 0 0"
        rpy="0 0 0" />
      <geometry>
        <mesh
          filename="package://simpledog/meshes/quadruped/Origin_rear_right_2_link.STL" />
      </geometry>
    </collision>
  </link>
  <joint
    name="RH_HFE"
    type="continuous">
    <origin
      xyz="0 0 0"
      rpy="-1.5708 0 0" />
    <parent
      link="RH_HIP" />
    <child
      link="RH_THIGH" />
    <axis
      xyz="0 0 1" />
      <limit
      effort="60"
      velocity="10"
      lower="-7.0"
      upper="7.0"/>

  </joint>
  <link
    name="RH_SHANK">
    <inertial>
      <origin
        xyz="0.202313 0.000199 0.225432"
        rpy="0 0 0" />
      <mass
        value="0.444569" />
      <inertia
        ixx="0.000385"
        ixy="0"
        ixz="0"
        iyy="0.006223"
        iyz="0"
        izz="0.006502"/>
    </inertial>
    <visual>
      <origin
        xyz="0 0 0"
        rpy="0 0 0" />
      <geometry>
        <mesh
          filename="package://simpledog/meshes/quadruped/Origin_rear_right_3_link.STL" />
      </geometry>
      <material
        name="">
        <color
          rgba="0.79216 0.81961 0.93333 1" />
      </material>
    </visual>
    <collision>
      <origin
        xyz="0 0 0"
        rpy="0 0 0" />
      <geometry>
        <mesh
          filename="package://simpledog/meshes/quadruped/Origin_rear_right_3_link.STL" />
      </geometry>
    </collision>
  </link>
  <joint
    name="RH_KFE"
    type="continuous">
    <origin
      xyz="0.308 0 0"
      rpy="0 0 0" />
    <parent
      link="RH_THIGH" />
    <child
      link="RH_SHANK" />
    <axis
      xyz="0 0 1" />
      <limit
      effort="60"
      velocity="10"
      lower="-3.0"
      upper="3.0"/>

  </joint>
  <link
    name="RH_FOOT">
    <inertial>
      <origin
        xyz="0.022126 -1.6187E-13 -1E-06"
        rpy="0 0 0" />
      <mass
        value="0.03332" />
      <inertia
        ixx="0.000014"
        ixy="0"
        ixz="0"
        iyy="0.000014"
        iyz="0"
        izz="0.000019" />
    </inertial>
    <visual>
      <origin
        xyz="0 0 0"
        rpy="0 0 0" />
      <geometry>
        <mesh
          filename="package://simpledog/meshes/quadruped/Origin_rr_foot_link.STL" />
      </geometry>
      <material
        name="">
        <color
          rgba="0 0 0 1" />
      </material>
    </visual>
    <collision>
      <origin
        xyz="0 0 0"
        rpy="0 0 0" />
      <geometry>
        <mesh
          filename="package://simpledog/meshes/quadruped/Origin_rr_foot_link.STL" />
      </geometry>
    </collision>
  </link>
  <joint
    name="RH_ADAPTER"
    type="fixed">
    <origin
      xyz="0.308 0 0.22053"
      rpy="0 0 0" />
    <parent
      link="RH_SHANK" />
    <child
      link="RH_FOOT" />
    <axis
      xyz="0 0 0" />
  </joint>
  <link
    name="LH_HIP">
    <inertial>
      <origin
        xyz="-0.000688 0.10488 0.003776"
        rpy="0 0 0" />
      <mass
        value="2.9231" />
      <inertia
        ixx="0.004820"
        ixy="0"
        ixz="0"
        iyy="0.007868"
        iyz="0"
        izz="0.008241" />
    </inertial>
    <visual>
      <origin
        xyz="0 0 0"
        rpy="0 0 0" />
      <geometry>
        <mesh
          filename="package://simpledog/meshes/quadruped/Origin_rear_left_1_link.STL" />
      </geometry>
      <material
        name="">
        <color
          rgba="0.79216 0.81961 0.93333 1" />
      </material>
    </visual>
    <collision>
      <origin
        xyz="0 0 0"
        rpy="0 0 0" />
      <geometry>
        <mesh
          filename="package://simpledog/meshes/quadruped/Origin_rear_left_1_link.STL" />
      </geometry>
    </collision>
  </link>
  <joint
    name="LH_HAA"
    type="revolute">
    <origin
      xyz="-0.427 0.075 -0.0095"
      rpy="0 1.5708 0" />
    <parent
      link="base" />
    <child
      link="LH_HIP" />
    <axis
      xyz="0 0 1" />
      <limit
      effort="60"
      velocity="10"
      lower="-3.0"
      upper="3.0"/>

  </joint>
  <link
    name="LH_THIGH">
    <inertial>
      <origin
        xyz="0.184717 3.2E-05 0.129056"
        rpy="0 0 0" />
      <mass
        value="4.216358" />
      <inertia
        ixx="0.006286"
        ixy="0"
        ixz="0"
        iyy="0.028156"
        iyz="0"
        izz="0.029242" />
    </inertial>
    <visual>
      <origin
        xyz="0 0 0"
        rpy="0 0 0" />
      <geometry>
        <mesh
          filename="package://simpledog/meshes/quadruped/Origin_rear_left_2_link.STL" />
      </geometry>
      <material
        name="">
        <color
          rgba="0.79216 0.81961 0.93333 1" />
      </material>
    </visual>
    <collision>
      <origin
        xyz="0 0 0"
        rpy="0 0 0" />
      <geometry>
        <mesh
          filename="package://simpledog/meshes/quadruped/Origin_rear_left_2_link.STL" />
      </geometry>
    </collision>
  </link>
  <joint
    name="LH_HFE"
    type="continuous">
    <origin
      xyz="0 0 0"
      rpy="-1.5708 0 0" />
    <parent
      link="LH_HIP" />
    <child
      link="LH_THIGH" />
    <axis
      xyz="0 0 1" />
      <limit
      effort="60"
      velocity="10"
      lower="-7.0"
      upper="7.0"/>

  </joint>
  <link
    name="LH_SHANK">
    <inertial>
      <origin
        xyz="0.202313 0.000199 0.225432"
        rpy="0 0 0" />
      <mass
        value="0.444569" />
      <inertia
        ixx="0.000385"
        ixy="0"
        ixz="0"
        iyy="0.006223"
        iyz="0"
        izz="0.006502" />
    </inertial>
    <visual>
      <origin
        xyz="0 0 0"
        rpy="0 0 0" />
      <geometry>
        <mesh
          filename="package://simpledog/meshes/quadruped/Origin_rear_left_3_link.STL" />
      </geometry>
      <material
        name="">
        <color
          rgba="0.79216 0.81961 0.93333 1" />
      </material>
    </visual>
    <collision>
      <origin
        xyz="0 0 0"
        rpy="0 0 0" />
      <geometry>
        <mesh
          filename="package://simpledog/meshes/quadruped/Origin_rear_left_3_link.STL" />
      </geometry>
    </collision>
  </link>
  <joint
    name="LH_KFE"
    type="continuous">
    <origin
      xyz="0.308 0 0"
      rpy="0 0 0" />
    <parent
      link="LH_THIGH" />
    <child
      link="LH_SHANK" />
    <axis
      xyz="0 0 1" />
      <limit
      effort="60"
      velocity="10"
      lower="-3.0"
      upper="3.0"/>

  </joint>
  <link
    name="LH_FOOT">
    <inertial>
      <origin
        xyz="0.022126 -7.7827E-14 0.00049896"
        rpy="0 0 0" />
      <mass
        value="0.03332" />
      <inertia
        ixx="0.000014"
        ixy="0"
        ixz="0"
        iyy="0.000014"
        iyz="0"
        izz="0.000019" />
    </inertial>
    <visual>
      <origin
        xyz="0 0 0"
        rpy="0 0 0" />
      <geometry>
        <mesh
          filename="package://simpledog/meshes/quadruped/Origin_rl_foot_link.STL" />
      </geometry>
      <material
        name="">
        <color
          rgba="0 0 0 1" />
      </material>
    </visual>
    <collision>
      <origin
        xyz="0 0 0"
        rpy="0 0 0" />
      <geometry>
        <mesh
          filename="package://simpledog/meshes/quadruped/Origin_rl_foot_link.STL" />
      </geometry>
    </collision>
  </link>
  <joint
    name="LH_ADAPTER"
    type="fixed">
    <origin
      xyz="0.308 0 0.23"
      rpy="0 0 0" />
    <parent
      link="LH_SHANK" />
    <child
      link="LH_FOOT" />
    <axis
      xyz="0 0 0" />
  </joint>
                <gazebo reference="LF_HIP">
                        <mu1 value="100.0"/>
                        <mu2 value="100.0"/>
                        <kp value="10000000.0" />
                        <kd value="1.0" />
                        <fdir1 value="1 0 0"/>
                </gazebo>
                <gazebo reference="LF_THIGH">
                        <mu1 value="100.0"/>
                        <mu2 value="100.0"/>
                        <kp value="10000000.0" />
                        <kd value="1.0" />
                        <fdir1 value="1 0 0"/>
                </gazebo>
                <gazebo reference="LF_SHANK">
                        <mu1 value="100.0"/>
                        <mu2 value="100.0"/>
                        <kp value="10000000.0" />
                        <kd value="1.0" />
                        <fdir1 value="1 0 0"/>
                </gazebo>
                <gazebo reference="RF_HIP">
                        <mu1 value="100.0"/>
                        <mu2 value="100.0"/>
                        <kp value="10000000.0" />
                        <kd value="1.0" />
                        <fdir1 value="1 0 0"/>
                </gazebo>
                <gazebo reference="RF_THIGH">
                        <mu1 value="100.0"/>
                        <mu2 value="100.0"/>
                        <kp value="10000000.0" />
                        <kd value="1.0" />
                        <fdir1 value="1 0 0"/>
                </gazebo>
                <gazebo reference="RF_SHANK">
                        <mu1 value="100.0"/>
                        <mu2 value="100.0"/>
                        <kp value="10000000.0" />
                        <kd value="1.0" />
                        <fdir1 value="1 0 0"/>
                </gazebo>
                <gazebo reference="LH_HIP">
                        <mu1 value="100.0"/>
                        <mu2 value="100.0"/>
                        <kp value="10000000.0" />
                        <kd value="1.0" />
                        <fdir1 value="1 0 0"/>
                </gazebo>
                <gazebo reference="LH_THIGH">
                        <mu1 value="100.0"/>
                        <mu2 value="100.0"/>
                        <kp value="10000000.0" />
                        <kd value="1.0" />
                        <fdir1 value="1 0 0"/>
                </gazebo>
                <gazebo reference="LH_SHANK">
                        <mu1 value="100.0"/>
                        <mu2 value="100.0"/>
                        <kp value="10000000.0" />
                        <kd value="1.0" />
                        <fdir1 value="1 0 0"/>
                </gazebo>
                <gazebo reference="RH_HIP">
                        <mu1 value="100.0"/>
                        <mu2 value="100.0"/>
                        <kp value="10000000.0" />
                        <kd value="1.0" />
                        <fdir1 value="1 0 0"/>
                </gazebo>
                <gazebo reference="RH_THIGH">
                        <mu1 value="100.0"/>
                        <mu2 value="100.0"/>
                        <kp value="10000000.0" />
                        <kd value="1.0" />
                        <fdir1 value="1 0 0"/>
                </gazebo>
                <gazebo reference="RH_SHANK">
                        <mu1 value="100.0"/>
                        <mu2 value="100.0"/>
                        <kp value="10000000.0" />
                        <kd value="1.0" />
                        <fdir1 value="1 0 0"/>
                </gazebo>

</robot>
