<?xml version="1.0" encoding="utf-8"?>
<!-- This URDF was automatically created by SolidWorks to URDF Exporter! Originally created by Stephen Brawner (brawner@gmail.com)
     Commit Version: 1.5.0-0-g9aa0fdb  Build Version: 1.5.7004.21443
     For more information, please see http://wiki.ros.org/sw_urdf_exporter -->
<robot name="quadruped_model" xmlns:xacro="http://ros.org/wiki/xacro">

    <xacro:include filename="$(find simpledog_description)/urdf/VLP-16.urdf.xacro"/>
    <VLP-16 parent="base">
        <origin xyz="0.26  0  0.118" rpy="0 0 0" />
    </VLP-16>

    <!--  <xacro:include filename="$(find simpledog)/urdf/rplidar.xacro" />
        <xacro:property name="rplidar_offset_x" value="0" />
        <xacro:property name="rplidar_offset_y" value="0" />
        <xacro:property name="rplidar_offset_z" value="0.12" />
        <joint name="rplidar_joint" type="fixed">
        <origin xyz="${rplidar_offset_x} ${rplidar_offset_y} ${rplidar_offset_z}" rpy="0 0 0" />
        <parent link="base_link"/>
        <child link="laser_link"/>
        </joint>

        <xacro:rplidar prefix="laser"/>    -->


    <link name="imu_link">
      <inertial>
        <mass value="0.1"/>
        <origin rpy="0 0 0" xyz="0 0 0"/>
        <inertia ixx="0.0001" ixy="0" ixz="0" iyy="0.000001" iyz="0" izz="0.0001"/>
      </inertial>
      <visual>
        <origin rpy="0 0 0" xyz="0 0 0"/>
        <geometry>
          <box size="0.06 0.06 0.02"/>
        </geometry>
      </visual>
      <collision>
        <origin rpy="0 0 0" xyz="0 0 0"/>
        <geometry>
          <box size="0.06 0.06 0.02"/>
        </geometry>
      </collision>
    </link>
    <joint name="imu_joint" type="fixed">
        <axis xyz="0 0 0"/> 
        <origin xyz="0.13 0 0.12" rpy="0 0 0"/>
        <parent link="base"/>
        <child link="imu_link"/>
    </joint>

  <!-- <xacro:arg name="laser_visual"  default="false"/> -->
  <!-- <xacro:arg name="camera_visual" default="false"/> -->
  <!-- <xacro:arg name="imu_visual"    default="false"/> -->
  <xacro:arg name="kinect_enabled"    default="true"/>
    <xacro:include filename="$(find simpledog_description)/urdf/simpledog_gazebo.urdf.xacro" />
    <xacro:include filename="$(find simpledog_description)/urdf/joint_gazebo.urdf.xacro" />
  <!--   <xacro:include filename="$(find simpledog_description)/urdf/_d435.urdf.xacro"/> -->
  <xacro:include filename="$(find simpledog_description)/urdf/stereo.urdf.xacro"/> 
   <xacro:include filename="$(find simpledog_description)/urdf/foot_sensor_gazebo.urdf.xacro" />
   <!-- <xacro:include filename="$(find simpledog_description)/urdf/kinect.urdf.xacro" /> -->
  <!--load kinect urdf-->
 <!--  <xacro:if value="$(arg kinect_enabled)">
    <xacro:kinect_camera prefix="camera" robot_namespace="$(arg robot_namespace)"/>
    <joint name="kinect_frame_joint" type="fixed">
      <origin xyz="0.5 0.0 0.0" rpy="0 0 0" />
      <parent link="base"/>
      <child link="camera_link"/>
    </joint>
  </xacro:if>   -->
  <xacro:if value="$(arg kinect_enabled)">
    <xacro:stereo_camera prefix="camera" robot_namespace="$(arg robot_namespace)"/>
    <joint name="stereo_frame_joint" type="fixed">
      <origin xyz="0.5 0.0 0.0" rpy="0 0 0" />
      <parent link="base"/>
      <child link="camera_link"/>
    </joint>
  </xacro:if> 
 <!--  <xacro:include filename="$(find simpledog_description)/urdf/_d435.urdf.xacro" />
     <xacro:sensor_d435 name="camera_d435" />
   <joint name="d435_frame_joint" type="fixed">
      <origin xyz="0.5 0.0 0.1" rpy="0 0 0" />
      <parent link="base"/>
      <child link="camera_d435_link"/>
    </joint> -->

  <!-- simple dog joints macros configure the joint driver and param-->
  <xacro:simpledog_joint joint_prefix="LF_HAA"> </xacro:simpledog_joint>
  <xacro:simpledog_joint joint_prefix="LF_HFE"> </xacro:simpledog_joint>
  <xacro:simpledog_joint joint_prefix="LF_KFE"> </xacro:simpledog_joint>
  <xacro:simpledog_joint joint_prefix="RF_HAA"> </xacro:simpledog_joint>
  <xacro:simpledog_joint joint_prefix="RF_HFE"> </xacro:simpledog_joint>
  <xacro:simpledog_joint joint_prefix="RF_KFE"> </xacro:simpledog_joint>
  <xacro:simpledog_joint joint_prefix="RH_HAA"> </xacro:simpledog_joint>
  <xacro:simpledog_joint joint_prefix="RH_HFE"> </xacro:simpledog_joint>
  <xacro:simpledog_joint joint_prefix="RH_KFE"> </xacro:simpledog_joint>
  <xacro:simpledog_joint joint_prefix="LH_HAA"> </xacro:simpledog_joint>
  <xacro:simpledog_joint joint_prefix="LH_HFE"> </xacro:simpledog_joint>
  <xacro:simpledog_joint joint_prefix="LH_KFE"> </xacro:simpledog_joint>

  <xacro:simpledog_foot_sensors foot_prefix="LF_FOOT" joint_prefix="LF_SHANK"> </xacro:simpledog_foot_sensors>
  <xacro:simpledog_foot_sensors foot_prefix="RF_FOOT" joint_prefix="RF_SHANK"> </xacro:simpledog_foot_sensors>
  <xacro:simpledog_foot_sensors foot_prefix="RH_FOOT" joint_prefix="RH_SHANK"> </xacro:simpledog_foot_sensors>
  <xacro:simpledog_foot_sensors foot_prefix="LH_FOOT" joint_prefix="LH_SHANK"> </xacro:simpledog_foot_sensors>

    <link name="base">
        <visual>
            <origin rpy="0 0 0" xyz="0 0 0"/>
            <geometry>
                <box size="0.001 0.001 0.001"/>
            </geometry>
        </visual>
    </link>

    <joint name="floating_base" type="fixed">
        <origin rpy="0 0 0" xyz="0 0 0"/>
        <parent link="base"/>
        <child link="base_inertia"/>
    </joint>


  <link
    name="base_inertia">
    <inertial>
      <origin
        xyz="0.006699 -0.000736 0.001288"
        rpy="0 0 0" />
      <mass
        value="27.801" />
      <inertia
        ixx="0.263893"
        ixy="0"
        ixz="0"
        iyy="2.018032"
        iyz="0"
        izz="2.056458" />
    </inertial>
    <visual>
      <origin
        xyz="0 0 0"
        rpy="0 0 0" />
      <geometry>
        <mesh
          filename="package://simpledog_description/meshes/quadruped/untitled.dae" />
      </geometry>
      <material
        name="">
        <color
          rgba="0.79216 0.81961 0.93333 1" />
      </material>
    </visual>
    <collision>
      <origin
        xyz="0 0 0"
        rpy="0 0 0" />
      <geometry>
        <mesh
          filename="package://simpledog_description/meshes/quadruped/untitled.dae" />
      </geometry>
    </collision>
  </link>
  <link
    name="LF_HIP">
    <inertial>
      <origin
        xyz="0.000688 0.10488 -0.003776"
        rpy="0 0 0" />
      <mass
        value="2.9231" />
      <inertia
        ixx="0.004820"
        ixy="0"
        ixz="0"
        iyy="0.007868"
        iyz="0"
        izz="0.008241" />
    </inertial>
    <visual>
      <origin
        xyz="0 0 0"
        rpy="0 0 0" />
      <geometry>
        <mesh
          filename="package://simpledog_description/meshes/quadruped/Origin_front_left_1_link.STL" />
      </geometry>
      <material
        name="">
        <color
          rgba="0.79216 0.81961 0.93333 1" />
      </material>
    </visual>
    <collision>
      <origin
        xyz="0 0 0"
        rpy="0 0 0" />
      <geometry>
        <mesh
          filename="package://simpledog_description/meshes/quadruped/Origin_front_left_1_link.STL" />
      </geometry>
    </collision>
  </link>
  <joint
    name="LF_HAA"
    type="revolute">
    <origin
      xyz="0.427 0.075 -0.0095"
      rpy="0 1.5708 0" />
    <parent
      link="base" />
    <child
      link="LF_HIP" />
    <axis
      xyz="0 0 1" />
      <limit
      effort="300"
      velocity="10"
      lower="-3.0"
      upper="3.0"/>

  </joint>
  <link
    name="LF_THIGH">
    <inertial>
      <origin
        xyz="0.18475 3.2E-05 0.12906"
        rpy="0 0 0" />
      <mass
        value="4.2164" />
      <inertia
        ixx="0.006286"
        ixy="0"
        ixz="0"
        iyy="0.028156"
        iyz="0"
        izz="0.029242" />
    </inertial>
    <visual>
      <origin
        xyz="0 0 0"
        rpy="0 0 0" />
      <geometry>
        <mesh
          filename="package://simpledog_description/meshes/quadruped/Origin_front_left_2_link.STL" />
      </geometry>
      <material
        name="">
        <color
          rgba="0.79216 0.81961 0.93333 1" />
      </material>
    </visual>
    <collision>
      <origin
        xyz="0 0 0"
        rpy="0 0 0" />
      <geometry>
        <mesh
          filename="package://simpledog_description/meshes/quadruped/Origin_front_left_2_link.STL" />
      </geometry>
    </collision>
  </link>
  <joint
    name="LF_HFE"
    type="continuous">
    <origin
      xyz="0 0 0"
      rpy="-1.5708 0 0" />
    <parent
      link="LF_HIP" />
    <child
      link="LF_THIGH" />
    <axis
      xyz="0 0 1" />
      <limit
      effort="300"
      velocity="10"
      lower="-7.0"
      upper="7.0"/>

  </joint>
  <link
    name="LF_SHANK">
    <inertial>
      <origin
        xyz="0.20231 0.000199 0.22543"
        rpy="0 0 0" />
      <mass
        value="0.44457" />
      <inertia
        ixx="0.000385"
        ixy="0"
        ixz="0"
        iyy="0.006223"
        iyz="0"
        izz="0.006502" />
    </inertial>
    <visual>
      <origin
        xyz="0 0 0"
        rpy="0 0 0" />
      <geometry>
        <mesh
          filename="package://simpledog_description/meshes/quadruped/Origin_front_left_3_link.STL" />
      </geometry>
      <material
        name="">
        <color
          rgba="0.79216 0.81961 0.93333 1" />
      </material>
    </visual>
    <collision>
      <origin
        xyz="0 0 0"
        rpy="0 0 0" />
      <geometry>
        <mesh
          filename="package://simpledog_description/meshes/quadruped/Origin_front_left_3_link.STL" />
      </geometry>
    </collision>
  </link>
  <joint
    name="LF_KFE"
    type="continuous">
    <origin
      xyz="0.308 0 0"
      rpy="0 0 0" />
    <parent
      link="LF_THIGH" />
    <child
      link="LF_SHANK" />
    <axis
      xyz="0 0 1" />
      <limit
      effort="300"
      velocity="10"
      lower="-3.0"
      upper="3.0"/>

  </joint>
  <link
    name="LF_FOOT">
    <inertial>
      <origin
        xyz="0.022126 -1.2357E-13 0.00049896"
        rpy="0 0 0" />
      <mass
        value="0.03332" />
      <inertia
        ixx="0.000014"
        ixy="0"
        ixz="0"
        iyy="0.000014"
        iyz="0"
        izz="0.000019" />
    </inertial>
    <visual>
      <origin
        xyz="0 0 0"
        rpy="0 0 0" />
      <geometry>
        <mesh
          filename="package://simpledog_description/meshes/quadruped/Origin_lf_foot_link.STL" />
      </geometry>
      <material
        name="">
        <color
          rgba="0 0 0 1" />
      </material>
    </visual>
    <collision>
      <origin
        xyz="0 0 0"
        rpy="0 0 0" />
      <geometry>
        <mesh
          filename="package://simpledog_description/meshes/quadruped/Origin_lf_foot_link.STL" />
      </geometry>
    </collision>
  </link>
  <joint
    name="LF_ADAPTER"
    type="fixed">
    <origin
      xyz="0.308 0 0.23"
      rpy="0 0 0" />
    <parent
      link="LF_SHANK" />
    <child
      link="LF_FOOT" />
    <axis
      xyz="0 0 0" />
  </joint>
  <link
    name="RF_HIP">
    <inertial>
      <origin
        xyz="-0.000688 0.104882 0.003776"
        rpy="0 0 0" />
      <mass
        value="2.923111" />
      <inertia
        ixx="0.004820"
        ixy="0"
        ixz="0"
        iyy="0.007868"
        iyz="0"
        izz="0.008241" />
    </inertial>
    <visual>
      <origin
        xyz="0 0 0"
        rpy="0 0 0" />
      <geometry>
        <mesh
          filename="package://simpledog_description/meshes/quadruped/Origin_front_right_1_link.STL" />
      </geometry>
      <material
        name="">
        <color
          rgba="0.79216 0.81961 0.93333 1" />
      </material>
    </visual>
    <collision>
      <origin
        xyz="0 0 0"
        rpy="0 0 0" />
      <geometry>
        <mesh
          filename="package://simpledog_description/meshes/quadruped/Origin_front_right_1_link.STL" />
      </geometry>
    </collision>
  </link>
  <joint
    name="RF_HAA"
    type="revolute">
    <origin
      xyz="0.427 -0.075 -0.0095"
      rpy="3.1416 1.5708 0" />
    <parent
      link="base" />
    <child
      link="RF_HIP" />
    <axis
      xyz="0 0 1" />
      <limit
      effort="300"
      velocity="10"
      lower="-3.0"
      upper="3.0"/>

  </joint>
  <link
    name="RF_THIGH">
    <inertial>
      <origin
        xyz="0.184747 3.2E-05 0.129056"
        rpy="0 0 0" />
      <mass
        value="4.216358" />
      <inertia
        ixx="0.006286"
        ixy="0"
        ixz="0"
        iyy="0.028156"
        iyz="0"
        izz="0.029242" />
    </inertial>
    <visual>
      <origin
        xyz="0 0 0"
        rpy="0 0 0" />
      <geometry>
        <mesh
          filename="package://simpledog_description/meshes/quadruped/Origin_front_right_2_link.STL" />
      </geometry>
      <material
        name="">
        <color
          rgba="0.79216 0.81961 0.93333 1" />
      </material>
    </visual>
    <collision>
      <origin
        xyz="0 0 0"
        rpy="0 0 0" />
      <geometry>
        <mesh
          filename="package://simpledog_description/meshes/quadruped/Origin_front_right_2_link.STL" />
      </geometry>
    </collision>
  </link>
  <joint
    name="RF_HFE"
    type="continuous">
    <origin
      xyz="0 0 0"
      rpy="-1.5708 0 0" />
    <parent
      link="RF_HIP" />
    <child
      link="RF_THIGH" />
    <axis
      xyz="0 0 1" />
      <limit
      effort="300"
      velocity="10"
      lower="-7.0"
      upper="7.0"/>

  </joint>
  <link
    name="RF_SHANK">
    <inertial>
      <origin
        xyz="0.202313 0.000199 0.225432"
        rpy="0 0 0" />
      <mass
        value="0.444569" />
      <inertia
        ixx="0.000385"
        ixy="0"
        ixz="0"
        iyy="0.006223"
        iyz="0"
        izz="0.006502" />
    </inertial>
    <visual>
      <origin
        xyz="0 0 0"
        rpy="0 0 0" />
      <geometry>
        <mesh
          filename="package://simpledog_description/meshes/quadruped/Origin_front_right_3_link.STL" />
      </geometry>
      <material
        name="">
        <color
          rgba="0.79216 0.81961 0.93333 1" />
      </material>
    </visual>
    <collision>
      <origin
        xyz="0 0 0"
        rpy="0 0 0" />
      <geometry>
        <mesh
          filename="package://simpledog_description/meshes/quadruped/Origin_front_right_3_link.STL" />
      </geometry>
    </collision>
  </link>
  <joint
    name="RF_KFE"
    type="continuous">
    <origin
      xyz="0.308 0 0"
      rpy="0 0 0" />
    <parent
      link="RF_THIGH" />
    <child
      link="RF_SHANK" />
    <axis
      xyz="0 0 1" />
      <limit
      effort="300"
      velocity="10"
      lower="-3.0"
      upper="3.0"/>

  </joint>
  <link
    name="RF_FOOT">
    <inertial>
      <origin
        xyz="0.022126 -4.4892E-13 -1.0375E-06"
        rpy="0 0 0" />
      <mass
        value="0.03332" />
      <inertia
        ixx="0.000014"
        ixy="0"
        ixz="0"
        iyy="0.000014"
        iyz="0"
        izz="0.000019" />
    </inertial>
    <visual>
      <origin
        xyz="0 0 0"
        rpy="0 0 0" />
      <geometry>
        <mesh
          filename="package://simpledog_description/meshes/quadruped/Orgin_rf_foot_link.STL" />
      </geometry>
      <material
        name="">
        <color
          rgba="0 0 0 1" />
      </material>
    </visual>
    <collision>
      <origin
        xyz="0 0 0"
        rpy="0 0 0" />
      <geometry>
        <mesh
          filename="package://simpledog_description/meshes/quadruped/Orgin_rf_foot_link.STL" />
      </geometry>
    </collision>
  </link>
  <joint
    name="RF_ADAPTER"
    type="fixed">
    <origin
      xyz="0.308 0 0.22053"
      rpy="0 0 0" />
    <parent
      link="RF_SHANK" />
    <child
      link="RF_FOOT" />
    <axis
      xyz="0 0 0" />
  </joint>
  <link
    name="RH_HIP">
    <inertial>
      <origin
        xyz="0.000688 0.104882 0.003776"
        rpy="0 0 0" />
      <mass
        value="2.923111" />
      <inertia
        ixx="0.004820"
        ixy="0"
        ixz="0"
        iyy="0.007868"
        iyz="0"
        izz="0.008241" />
    </inertial>
    <visual>
      <origin
        xyz="0 0 0"
        rpy="0 0 0" />
      <geometry>
        <mesh
          filename="package://simpledog_description/meshes/quadruped/Origin_rear_right_1_link.STL" />
      </geometry>
      <material
        name="">
        <color
          rgba="0.79216 0.81961 0.93333 1" />
      </material>
    </visual>
    <collision>
      <origin
        xyz="0 0 0"
        rpy="0 0 0" />
      <geometry>
        <mesh
          filename="package://simpledog_description/meshes/quadruped/Origin_rear_right_1_link.STL" />
      </geometry>
    </collision>
  </link>
  <joint
    name="RH_HAA"
    type="revolute">
    <origin
      xyz="-0.427 -0.075 -0.0095"
      rpy="3.1416 1.5708 0" />
    <parent
      link="base" />
    <child
      link="RH_HIP" />
    <axis
      xyz="0 0 1" />
      <limit
      effort="300"
      velocity="10"
      lower="-3.0"
      upper="3.0"/>

  </joint>
  <link
    name="RH_THIGH">
    <inertial>
      <origin
        xyz="0.184747 3.2E-05 0.129056"
        rpy="0 0 0" />
      <mass
        value="4.216358" />
      <inertia
        ixx="0.006286"
        ixy="0"
        ixz="0"
        iyy="0.028156"
        iyz="0"
        izz="0.029242" />
    </inertial>
    <visual>
      <origin
        xyz="0 0 0"
        rpy="0 0 0" />
      <geometry>
        <mesh
          filename="package://simpledog_description/meshes/quadruped/Origin_rear_right_2_link.STL" />
      </geometry>
      <material
        name="">
        <color
          rgba="0.79216 0.81961 0.93333 1" />
      </material>
    </visual>
    <collision>
      <origin
        xyz="0 0 0"
        rpy="0 0 0" />
      <geometry>
        <mesh
          filename="package://simpledog_description/meshes/quadruped/Origin_rear_right_2_link.STL" />
      </geometry>
    </collision>
  </link>
  <joint
    name="RH_HFE"
    type="continuous">
    <origin
      xyz="0 0 0"
      rpy="-1.5708 0 0" />
    <parent
      link="RH_HIP" />
    <child
      link="RH_THIGH" />
    <axis
      xyz="0 0 1" />
      <limit
      effort="300"
      velocity="10"
      lower="-7.0"
      upper="7.0"/>

  </joint>
  <link
    name="RH_SHANK">
    <inertial>
      <origin
        xyz="0.202313 0.000199 0.225432"
        rpy="0 0 0" />
      <mass
        value="0.444569" />
      <inertia
        ixx="0.000385"
        ixy="0"
        ixz="0"
        iyy="0.006223"
        iyz="0"
        izz="0.006502"/>
    </inertial>
    <visual>
      <origin
        xyz="0 0 0"
        rpy="0 0 0" />
      <geometry>
        <mesh
          filename="package://simpledog_description/meshes/quadruped/Origin_rear_right_3_link.STL" />
      </geometry>
      <material
        name="">
        <color
          rgba="0.79216 0.81961 0.93333 1" />
      </material>
    </visual>
    <collision>
      <origin
        xyz="0 0 0"
        rpy="0 0 0" />
      <geometry>
        <mesh
          filename="package://simpledog_description/meshes/quadruped/Origin_rear_right_3_link.STL" />
      </geometry>
    </collision>
  </link>
  <joint
    name="RH_KFE"
    type="continuous">
    <origin
      xyz="0.308 0 0"
      rpy="0 0 0" />
    <parent
      link="RH_THIGH" />
    <child
      link="RH_SHANK" />
    <axis
      xyz="0 0 1" />
      <limit
      effort="300"
      velocity="10"
      lower="-3.0"
      upper="3.0"/>

  </joint>
  <link
    name="RH_FOOT">
    <inertial>
      <origin
        xyz="0.022126 -1.6187E-13 -1E-06"
        rpy="0 0 0" />
      <mass
        value="0.03332" />
      <inertia
        ixx="0.000014"
        ixy="0"
        ixz="0"
        iyy="0.000014"
        iyz="0"
        izz="0.000019" />
    </inertial>
    <visual>
      <origin
        xyz="0 0 0"
        rpy="0 0 0" />
      <geometry>
        <mesh
          filename="package://simpledog_description/meshes/quadruped/Origin_rr_foot_link.STL" />
      </geometry>
      <material
        name="">
        <color
          rgba="0 0 0 1" />
      </material>
    </visual>
    <collision>
      <origin
        xyz="0 0 0"
        rpy="0 0 0" />
      <geometry>
        <mesh
          filename="package://simpledog_description/meshes/quadruped/Origin_rr_foot_link.STL" />
      </geometry>
    </collision>
  </link>
  <joint
    name="RH_ADAPTER"
    type="fixed">
    <origin
      xyz="0.308 0 0.22053"
      rpy="0 0 0" />
    <parent
      link="RH_SHANK" />
    <child
      link="RH_FOOT" />
    <axis
      xyz="0 0 0" />
  </joint>
  <link
    name="LH_HIP">
    <inertial>
      <origin
        xyz="-0.000688 0.10488 0.003776"
        rpy="0 0 0" />
      <mass
        value="2.9231" />
      <inertia
        ixx="0.004820"
        ixy="0"
        ixz="0"
        iyy="0.007868"
        iyz="0"
        izz="0.008241" />
    </inertial>
    <visual>
      <origin
        xyz="0 0 0"
        rpy="0 0 0" />
      <geometry>
        <mesh
          filename="package://simpledog_description/meshes/quadruped/Origin_rear_left_1_link.STL" />
      </geometry>
      <material
        name="">
        <color
          rgba="0.79216 0.81961 0.93333 1" />
      </material>
    </visual>
    <collision>
      <origin
        xyz="0 0 0"
        rpy="0 0 0" />
      <geometry>
        <mesh
          filename="package://simpledog_description/meshes/quadruped/Origin_rear_left_1_link.STL" />
      </geometry>
    </collision>
  </link>
  <joint
    name="LH_HAA"
    type="revolute">
    <origin
      xyz="-0.427 0.075 -0.0095"
      rpy="0 1.5708 0" />
    <parent
      link="base" />
    <child
      link="LH_HIP" />
    <axis
      xyz="0 0 1" />
      <limit
      effort="300"
      velocity="10"
      lower="-3.0"
      upper="3.0"/>

  </joint>
  <link
    name="LH_THIGH">
    <inertial>
      <origin
        xyz="0.184717 3.2E-05 0.129056"
        rpy="0 0 0" />
      <mass
        value="4.216358" />
      <inertia
        ixx="0.006286"
        ixy="0"
        ixz="0"
        iyy="0.028156"
        iyz="0"
        izz="0.029242" />
    </inertial>
    <visual>
      <origin
        xyz="0 0 0"
        rpy="0 0 0" />
      <geometry>
        <mesh
          filename="package://simpledog_description/meshes/quadruped/Origin_rear_left_2_link.STL" />
      </geometry>
      <material
        name="">
        <color
          rgba="0.79216 0.81961 0.93333 1" />
      </material>
    </visual>
    <collision>
      <origin
        xyz="0 0 0"
        rpy="0 0 0" />
      <geometry>
        <mesh
          filename="package://simpledog_description/meshes/quadruped/Origin_rear_left_2_link.STL" />
      </geometry>
    </collision>
  </link>
  <joint
    name="LH_HFE"
    type="continuous">
    <origin
      xyz="0 0 0"
      rpy="-1.5708 0 0" />
    <parent
      link="LH_HIP" />
    <child
      link="LH_THIGH" />
    <axis
      xyz="0 0 1" />
      <limit
      effort="300"
      velocity="10"
      lower="-7.0"
      upper="7.0"/>

  </joint>
  <link
    name="LH_SHANK">
    <inertial>
      <origin
        xyz="0.202313 0.000199 0.225432"
        rpy="0 0 0" />
      <mass
        value="0.444569" />
      <inertia
        ixx="0.000385"
        ixy="0"
        ixz="0"
        iyy="0.006223"
        iyz="0"
        izz="0.006502" />
    </inertial>
    <visual>
      <origin
        xyz="0 0 0"
        rpy="0 0 0" />
      <geometry>
        <mesh
          filename="package://simpledog_description/meshes/quadruped/Origin_rear_left_3_link.STL" />
      </geometry>
      <material
        name="">
        <color
          rgba="0.79216 0.81961 0.93333 1" />
      </material>
    </visual>
    <collision>
      <origin
        xyz="0 0 0"
        rpy="0 0 0" />
      <geometry>
        <mesh
          filename="package://simpledog_description/meshes/quadruped/Origin_rear_left_3_link.STL" />
      </geometry>
    </collision>
  </link>
  <joint
    name="LH_KFE"
    type="continuous">
    <origin
      xyz="0.308 0 0"
      rpy="0 0 0" />
    <parent
      link="LH_THIGH" />
    <child
      link="LH_SHANK" />
    <axis
      xyz="0 0 1" />
      <limit
      effort="300"
      velocity="10"
      lower="-3.0"
      upper="3.0"/>

  </joint>
  <link
    name="LH_FOOT">
    <inertial>
      <origin
        xyz="0.022126 -7.7827E-14 0.00049896"
        rpy="0 0 0" />
      <mass
        value="0.03332" />
      <inertia
        ixx="0.000014"
        ixy="0"
        ixz="0"
        iyy="0.000014"
        iyz="0"
        izz="0.000019" />
    </inertial>
    <visual>
      <origin
        xyz="0 0 0"
        rpy="0 0 0" />
      <geometry>
        <mesh
          filename="package://simpledog_description/meshes/quadruped/Origin_rl_foot_link.STL" />
      </geometry>
      <material
        name="">
        <color
          rgba="0 0 0 1" />
      </material>
    </visual>
    <collision>
      <origin
        xyz="0 0 0"
        rpy="0 0 0" />
      <geometry>
        <mesh
          filename="package://simpledog_description/meshes/quadruped/Origin_rl_foot_link.STL" />
      </geometry>
    </collision>
  </link>
  <joint
    name="LH_ADAPTER"
    type="fixed">
    <origin
      xyz="0.308 0 0.23"
      rpy="0 0 0" />
    <parent
      link="LH_SHANK" />
    <child
      link="LH_FOOT" />
    <axis
      xyz="0 0 0" />
  </joint>


<!--  <link
    name="base_wheel">
    <inertial>
      <origin
        xyz="0 0 0"
        rpy="0 0 0" />
      <mass
        value="0.12006" />
      <inertia
        ixx="2.6585E-05"
        ixy="2.7219E-21"
        ixz="-3.7146E-22"
        iyy="1.0699E-05"
        iyz="-1.8974E-22"
        izz="3.5324E-05" />
    </inertial>
    <visual>
      <origin
        xyz="0 0 0"
        rpy="0 0 0" />
      <geometry>
        <mesh
          filename="package://simpledog_description/meshes/chassis.dae" />
      </geometry>
      <material
        name="">
        <color
          rgba="0.52941 0.54902 0.54902 1" />
      </material>
    </visual>
    <collision>
      <origin
        xyz="0 0 0"
        rpy="0 0 0" />
      <geometry>
        <mesh
          filename="package://simpledog_description/meshes/chassis.dae" />
      </geometry>
    </collision>
  </link>
    <joint
    name="base_wheel_joint"
    type="fixed">
    <origin
      xyz="0 0 -0.08"
      rpy="0 0 0" />
    <parent
      link="base" />
    <child
      link="base_wheel" />
    <axis
      xyz="0 0 0" />
  </joint>
  <link
    name="left_wheel">
    <inertial>
      <origin
        xyz="0 0 0"
        rpy="0 0 0" />
      <mass
        value="3.02006" />
      <inertia
        ixx="2.6585E-05"
        ixy="2.7219E-21"
        ixz="-3.7146E-22"
        iyy="1.0699E-05"
        iyz="-1.8974E-22"
        izz="3.5324E-05" />
    </inertial>
    <visual>
      <origin
        xyz="0 0 0"
        rpy="0 0 0" />
      <geometry>
        <mesh
          filename="package://simpledog_description/meshes/wheel.dae" />
      </geometry>
      <material
        name="">
        <color
          rgba="0.52941 0.54902 0.54902 1" />
      </material>
    </visual>
    <collision>
      <origin
        xyz="0 0 0"
        rpy="0 0 0" />
      <geometry>
        <mesh
          filename="package://simpledog_description/meshes/wheel.dae" />
      </geometry>
    </collision>
  </link>
    <joint
    name="left_wheel_joint"
    type="continuous">
    <origin
      xyz="0 0.18 -0.1"
      rpy="0 0 0" />
    <parent
      link="base_wheel" />
    <child
      link="left_wheel" />
    <axis
      xyz="0 1 0" />
  </joint>
  <link
    name="right_wheel">
    <inertial>
      <origin
        xyz="0 0 0"
        rpy="0 0 0" />
      <mass
        value="3.02006" />
      <inertia
        ixx="2.6585E-05"
        ixy="2.7219E-21"
        ixz="-3.7146E-22"
        iyy="1.0699E-05"
        iyz="-1.8974E-22"
        izz="3.5324E-05" />
    </inertial>
    <visual>
      <origin
        xyz="0 0 0"
        rpy="0 0 0" />
      <geometry>
        <mesh
          filename="package://simpledog_description/meshes/wheel.dae" />
      </geometry>
      <material
        name="">
        <color
          rgba="0.52941 0.54902 0.54902 1" />
      </material>
    </visual>
    <collision>
      <origin
        xyz="0 0 0"
        rpy="0 0 0" />
      <geometry>
        <mesh
          filename="package://simpledog_description/meshes/wheel.dae" />
      </geometry>
    </collision>
  </link>
    <joint
    name="right_wheel_joint"
    type="continuous">
    <origin
      xyz="0 -0.18 -0.1"
      rpy="0 0 0" />
    <parent
      link="base_wheel" />
    <child
      link="right_wheel" />
    <axis
      xyz="0 1 0" />
  </joint>
  <link
    name="front_wheel">
    <inertial>
      <origin

        xyz="0 0 0"
        rpy="0 0 0" />
      <mass
        value="2.02006" />
      <inertia
        ixx="2.6585E-05"
        ixy="2.7219E-21"
        ixz="-3.7146E-22"
        iyy="1.0699E-05"
        iyz="-1.8974E-22"
        izz="3.5324E-05" />
    </inertial>
    <visual>
      <origin
        xyz="0 0 0"
        rpy="0 0 0" />
      <geometry>
        <sphere radius="0.06"/>
      </geometry>
      <material
        name="">
        <color
          rgba="0.52941 0.54902 0.54902 1" />
      </material>
    </visual>
    <collision>
      <origin
        xyz="0 0 0"
        rpy="0 0 0" />
      <geometry>
          <sphere radius="0.06"/>
      </geometry>
    </collision>
  </link>
    <joint
    name="front_wheel_joint"
    type="continuous">
    <origin
      xyz="0.2 0 -0.15"
      rpy="0 0 0" />
    <parent

      link="base_wheel" />
    <child
      link="front_wheel" />
    <axis
      xyz="0 1 1" />
  </joint>
  <link
    name="rear_wheel">
    <inertial>
      <origin
        xyz="0 0 0"
        rpy="0 0 0" />
      <mass
        value="2.02006" />
      <inertia
        ixx="2.6585E-05"
        ixy="2.7219E-21"
        ixz="-3.7146E-22"
        iyy="1.0699E-05"
        iyz="-1.8974E-22"
        izz="3.5324E-05" />
    </inertial>
    <visual>
      <origin
        xyz="0 0 0"
        rpy="0 0 0" />
      <geometry>
        <sphere radius="0.06"/>
      </geometry>
      <material
        name="">
        <color
          rgba="0.52941 0.54902 0.54902 1" />
      </material>
    </visual>
    <collision>
      <origin
        xyz="0 0 0"
        rpy="0 0 0" />
      <geometry>
          <sphere radius="0.06"/>
      </geometry>
    </collision>
  </link>
    <joint
    name="rear_wheel_joint"
    type="continuous">
    <origin
      xyz="-0.2 0 -0.15"
      rpy="0 0 0" />
    <parent
      link="base_wheel" />
    <child
      link="rear_wheel" />
    <axis
      xyz="0 1 1" />
  </joint>
  <transmission name="RF_joint_trans">
      <type>transmission_interface/SimpleTransmission</type>
      <joint name="right_wheel_joint" />
      <actuator name="RF_joint_motor">
          <hardwareInterface>VelocityJointInterface</hardwareInterface>
          <mechanicalReduction>1</mechanicalReduction>
      </actuator>
  </transmission>
  <transmission name="LF_joint_trans">
      <type>transmission_interface/SimpleTransmission</type>
      <joint name="left_wheel_joint" />
      <actuator name="LF_joint_motor">
          <hardwareInterface>VelocityJointInterface</hardwareInterface>
          <mechanicalReduction>1</mechanicalReduction>
      </actuator>
  </transmission>
  <gazebo>
    <plugin name="differential_drive_controller" filename="libgazebo_ros_diff_drive.so">
        <alwaysOn>true</alwaysOn>
        <updateRate>50.0</updateRate>
        <leftJoint>left_wheel_joint</leftJoint>
        <rightJoint>right_wheel_joint</rightJoint>
        <wheelSeparation>0.36</wheelSeparation>
        <wheelDiameter>0.22</wheelDiameter>
        <torque>50.0</torque>
        <commandTopic>wheel_cmd_vel</commandTopic>
        <odometryTopic>wheel_odom</odometryTopic>
        <odometryFrame>wheel_odom</odometryFrame>
        <robotBaseFrame>base</robotBaseFrame>
        <publishWheelTF>false</publishWheelTF>
        <publishWheelJointState>false</publishWheelJointState>
        <legecyMode>false</legecyMode>
        <wheelAcceleration>1</wheelAcceleration>
    </plugin>
  </gazebo>
          <gazebo reference="right_wheel">
              <mu1 value="10.0"/>
              <mu2 value="10.0"/>
          </gazebo>
          <gazebo reference="left_wheel">
              <mu1 value="10.0"/>
              <mu2 value="10.0"/>
          </gazebo> -->
</robot>
